{
 "cells": [
  {
   "cell_type": "code",
   "execution_count": 55,
   "metadata": {},
   "outputs": [],
   "source": [
    "import pandas as pd\n",
    "import numpy as np\n",
    "import tensorflow as tf\n",
    "from sklearn.feature_extraction.text import TfidfVectorizer\n",
    "from sklearn.preprocessing import LabelEncoder\n",
    "from tensorflow.keras.models import Sequential\n",
    "from tensorflow.keras.layers import Dense\n",
    "from keras.utils import to_categorical"
   ]
  },
  {
   "cell_type": "code",
   "execution_count": 56,
   "metadata": {},
   "outputs": [],
   "source": [
    "data = pd.read_csv('content_by_metadata.csv')\n",
    "dataset = data.values"
   ]
  },
  {
   "cell_type": "code",
   "execution_count": 57,
   "metadata": {},
   "outputs": [],
   "source": [
    "X = dataset[:,7]\n",
    "Y = dataset[:,6]"
   ]
  },
  {
   "cell_type": "code",
   "execution_count": 58,
   "metadata": {},
   "outputs": [],
   "source": [
    "encoder = LabelEncoder()\n",
    "encoder.fit(Y)\n",
    "encoded_Y = encoder.transform(Y)\n",
    "\n",
    "y = to_categorical(encoded_Y)"
   ]
  },
  {
   "cell_type": "code",
   "execution_count": 62,
   "metadata": {},
   "outputs": [],
   "source": [
    "model = Sequential()\n",
    "model.add(Dense(256, activation='relu', input_dim=1))\n",
    "model.add(Dense(128, activation='relu'))\n",
    "model.add(Dense(64, activation='relu'))\n",
    "model.add(Dense(19, activation='softmax'))"
   ]
  },
  {
   "cell_type": "code",
   "execution_count": 63,
   "metadata": {},
   "outputs": [],
   "source": [
    "optimizer = tf.keras.optimizers.Adam(learning_rate=0.001)\n",
    "model.compile(loss='categorical_crossentropy', optimizer=optimizer, metrics=['accuracy'])"
   ]
  },
  {
   "cell_type": "code",
   "execution_count": 64,
   "metadata": {},
   "outputs": [
    {
     "name": "stdout",
     "output_type": "stream",
     "text": [
      "Epoch 1/100\n"
     ]
    },
    {
     "ename": "UnimplementedError",
     "evalue": "Graph execution error:\n\nDetected at node sequential_8/Cast defined at (most recent call last):\n  File \"<frozen runpy>\", line 198, in _run_module_as_main\n\n  File \"<frozen runpy>\", line 88, in _run_code\n\n  File \"C:\\Users\\ASUS\\AppData\\Roaming\\Python\\Python311\\site-packages\\ipykernel_launcher.py\", line 17, in <module>\n\n  File \"C:\\Users\\ASUS\\AppData\\Roaming\\Python\\Python311\\site-packages\\traitlets\\config\\application.py\", line 1077, in launch_instance\n\n  File \"C:\\Users\\ASUS\\AppData\\Roaming\\Python\\Python311\\site-packages\\ipykernel\\kernelapp.py\", line 739, in start\n\n  File \"C:\\Users\\ASUS\\AppData\\Roaming\\Python\\Python311\\site-packages\\tornado\\platform\\asyncio.py\", line 205, in start\n\n  File \"c:\\Users\\ASUS\\AppData\\Local\\Programs\\Python\\Python311\\Lib\\asyncio\\base_events.py\", line 607, in run_forever\n\n  File \"c:\\Users\\ASUS\\AppData\\Local\\Programs\\Python\\Python311\\Lib\\asyncio\\base_events.py\", line 1922, in _run_once\n\n  File \"c:\\Users\\ASUS\\AppData\\Local\\Programs\\Python\\Python311\\Lib\\asyncio\\events.py\", line 80, in _run\n\n  File \"C:\\Users\\ASUS\\AppData\\Roaming\\Python\\Python311\\site-packages\\ipykernel\\kernelbase.py\", line 529, in dispatch_queue\n\n  File \"C:\\Users\\ASUS\\AppData\\Roaming\\Python\\Python311\\site-packages\\ipykernel\\kernelbase.py\", line 518, in process_one\n\n  File \"C:\\Users\\ASUS\\AppData\\Roaming\\Python\\Python311\\site-packages\\ipykernel\\kernelbase.py\", line 424, in dispatch_shell\n\n  File \"C:\\Users\\ASUS\\AppData\\Roaming\\Python\\Python311\\site-packages\\ipykernel\\kernelbase.py\", line 766, in execute_request\n\n  File \"C:\\Users\\ASUS\\AppData\\Roaming\\Python\\Python311\\site-packages\\ipykernel\\ipkernel.py\", line 429, in do_execute\n\n  File \"C:\\Users\\ASUS\\AppData\\Roaming\\Python\\Python311\\site-packages\\ipykernel\\zmqshell.py\", line 549, in run_cell\n\n  File \"C:\\Users\\ASUS\\AppData\\Roaming\\Python\\Python311\\site-packages\\IPython\\core\\interactiveshell.py\", line 3048, in run_cell\n\n  File \"C:\\Users\\ASUS\\AppData\\Roaming\\Python\\Python311\\site-packages\\IPython\\core\\interactiveshell.py\", line 3103, in _run_cell\n\n  File \"C:\\Users\\ASUS\\AppData\\Roaming\\Python\\Python311\\site-packages\\IPython\\core\\async_helpers.py\", line 129, in _pseudo_sync_runner\n\n  File \"C:\\Users\\ASUS\\AppData\\Roaming\\Python\\Python311\\site-packages\\IPython\\core\\interactiveshell.py\", line 3308, in run_cell_async\n\n  File \"C:\\Users\\ASUS\\AppData\\Roaming\\Python\\Python311\\site-packages\\IPython\\core\\interactiveshell.py\", line 3490, in run_ast_nodes\n\n  File \"C:\\Users\\ASUS\\AppData\\Roaming\\Python\\Python311\\site-packages\\IPython\\core\\interactiveshell.py\", line 3550, in run_code\n\n  File \"C:\\Users\\ASUS\\AppData\\Local\\Temp\\ipykernel_18508\\886818541.py\", line 1, in <module>\n\n  File \"c:\\Users\\ASUS\\AppData\\Local\\Programs\\Python\\Python311\\Lib\\site-packages\\keras\\src\\utils\\traceback_utils.py\", line 65, in error_handler\n\n  File \"c:\\Users\\ASUS\\AppData\\Local\\Programs\\Python\\Python311\\Lib\\site-packages\\keras\\src\\engine\\training.py\", line 1807, in fit\n\n  File \"c:\\Users\\ASUS\\AppData\\Local\\Programs\\Python\\Python311\\Lib\\site-packages\\keras\\src\\engine\\training.py\", line 1401, in train_function\n\n  File \"c:\\Users\\ASUS\\AppData\\Local\\Programs\\Python\\Python311\\Lib\\site-packages\\keras\\src\\engine\\training.py\", line 1384, in step_function\n\n  File \"c:\\Users\\ASUS\\AppData\\Local\\Programs\\Python\\Python311\\Lib\\site-packages\\keras\\src\\engine\\training.py\", line 1373, in run_step\n\n  File \"c:\\Users\\ASUS\\AppData\\Local\\Programs\\Python\\Python311\\Lib\\site-packages\\keras\\src\\engine\\training.py\", line 1150, in train_step\n\n  File \"c:\\Users\\ASUS\\AppData\\Local\\Programs\\Python\\Python311\\Lib\\site-packages\\keras\\src\\utils\\traceback_utils.py\", line 65, in error_handler\n\n  File \"c:\\Users\\ASUS\\AppData\\Local\\Programs\\Python\\Python311\\Lib\\site-packages\\keras\\src\\engine\\training.py\", line 590, in __call__\n\n  File \"c:\\Users\\ASUS\\AppData\\Local\\Programs\\Python\\Python311\\Lib\\site-packages\\keras\\src\\utils\\traceback_utils.py\", line 65, in error_handler\n\n  File \"c:\\Users\\ASUS\\AppData\\Local\\Programs\\Python\\Python311\\Lib\\site-packages\\keras\\src\\engine\\base_layer.py\", line 1149, in __call__\n\n  File \"c:\\Users\\ASUS\\AppData\\Local\\Programs\\Python\\Python311\\Lib\\site-packages\\keras\\src\\utils\\traceback_utils.py\", line 96, in error_handler\n\n  File \"c:\\Users\\ASUS\\AppData\\Local\\Programs\\Python\\Python311\\Lib\\site-packages\\keras\\src\\engine\\sequential.py\", line 398, in call\n\n  File \"c:\\Users\\ASUS\\AppData\\Local\\Programs\\Python\\Python311\\Lib\\site-packages\\keras\\src\\engine\\functional.py\", line 515, in call\n\n  File \"c:\\Users\\ASUS\\AppData\\Local\\Programs\\Python\\Python311\\Lib\\site-packages\\keras\\src\\engine\\functional.py\", line 654, in _run_internal_graph\n\n  File \"c:\\Users\\ASUS\\AppData\\Local\\Programs\\Python\\Python311\\Lib\\site-packages\\keras\\src\\engine\\functional.py\", line 751, in _conform_to_reference_input\n\nCast string to float is not supported\n\t [[{{node sequential_8/Cast}}]] [Op:__inference_train_function_5128]",
     "output_type": "error",
     "traceback": [
      "\u001b[1;31m---------------------------------------------------------------------------\u001b[0m",
      "\u001b[1;31mUnimplementedError\u001b[0m                        Traceback (most recent call last)",
      "\u001b[1;32mUntitled-1.ipynb Cell 7\u001b[0m line \u001b[0;36m1\n\u001b[1;32m----> <a href='vscode-notebook-cell:Untitled-1.ipynb?jupyter-notebook#W6sdW50aXRsZWQ%3D?line=0'>1</a>\u001b[0m model\u001b[39m.\u001b[39;49mfit(X, y, epochs\u001b[39m=\u001b[39;49m\u001b[39m100\u001b[39;49m, batch_size\u001b[39m=\u001b[39;49m\u001b[39m32\u001b[39;49m)\n",
      "File \u001b[1;32mc:\\Users\\ASUS\\AppData\\Local\\Programs\\Python\\Python311\\Lib\\site-packages\\keras\\src\\utils\\traceback_utils.py:70\u001b[0m, in \u001b[0;36mfilter_traceback.<locals>.error_handler\u001b[1;34m(*args, **kwargs)\u001b[0m\n\u001b[0;32m     67\u001b[0m     filtered_tb \u001b[39m=\u001b[39m _process_traceback_frames(e\u001b[39m.\u001b[39m__traceback__)\n\u001b[0;32m     68\u001b[0m     \u001b[39m# To get the full stack trace, call:\u001b[39;00m\n\u001b[0;32m     69\u001b[0m     \u001b[39m# `tf.debugging.disable_traceback_filtering()`\u001b[39;00m\n\u001b[1;32m---> 70\u001b[0m     \u001b[39mraise\u001b[39;00m e\u001b[39m.\u001b[39mwith_traceback(filtered_tb) \u001b[39mfrom\u001b[39;00m \u001b[39mNone\u001b[39;00m\n\u001b[0;32m     71\u001b[0m \u001b[39mfinally\u001b[39;00m:\n\u001b[0;32m     72\u001b[0m     \u001b[39mdel\u001b[39;00m filtered_tb\n",
      "File \u001b[1;32mc:\\Users\\ASUS\\AppData\\Local\\Programs\\Python\\Python311\\Lib\\site-packages\\tensorflow\\python\\eager\\execute.py:53\u001b[0m, in \u001b[0;36mquick_execute\u001b[1;34m(op_name, num_outputs, inputs, attrs, ctx, name)\u001b[0m\n\u001b[0;32m     51\u001b[0m \u001b[39mtry\u001b[39;00m:\n\u001b[0;32m     52\u001b[0m   ctx\u001b[39m.\u001b[39mensure_initialized()\n\u001b[1;32m---> 53\u001b[0m   tensors \u001b[39m=\u001b[39m pywrap_tfe\u001b[39m.\u001b[39mTFE_Py_Execute(ctx\u001b[39m.\u001b[39m_handle, device_name, op_name,\n\u001b[0;32m     54\u001b[0m                                       inputs, attrs, num_outputs)\n\u001b[0;32m     55\u001b[0m \u001b[39mexcept\u001b[39;00m core\u001b[39m.\u001b[39m_NotOkStatusException \u001b[39mas\u001b[39;00m e:\n\u001b[0;32m     56\u001b[0m   \u001b[39mif\u001b[39;00m name \u001b[39mis\u001b[39;00m \u001b[39mnot\u001b[39;00m \u001b[39mNone\u001b[39;00m:\n",
      "\u001b[1;31mUnimplementedError\u001b[0m: Graph execution error:\n\nDetected at node sequential_8/Cast defined at (most recent call last):\n  File \"<frozen runpy>\", line 198, in _run_module_as_main\n\n  File \"<frozen runpy>\", line 88, in _run_code\n\n  File \"C:\\Users\\ASUS\\AppData\\Roaming\\Python\\Python311\\site-packages\\ipykernel_launcher.py\", line 17, in <module>\n\n  File \"C:\\Users\\ASUS\\AppData\\Roaming\\Python\\Python311\\site-packages\\traitlets\\config\\application.py\", line 1077, in launch_instance\n\n  File \"C:\\Users\\ASUS\\AppData\\Roaming\\Python\\Python311\\site-packages\\ipykernel\\kernelapp.py\", line 739, in start\n\n  File \"C:\\Users\\ASUS\\AppData\\Roaming\\Python\\Python311\\site-packages\\tornado\\platform\\asyncio.py\", line 205, in start\n\n  File \"c:\\Users\\ASUS\\AppData\\Local\\Programs\\Python\\Python311\\Lib\\asyncio\\base_events.py\", line 607, in run_forever\n\n  File \"c:\\Users\\ASUS\\AppData\\Local\\Programs\\Python\\Python311\\Lib\\asyncio\\base_events.py\", line 1922, in _run_once\n\n  File \"c:\\Users\\ASUS\\AppData\\Local\\Programs\\Python\\Python311\\Lib\\asyncio\\events.py\", line 80, in _run\n\n  File \"C:\\Users\\ASUS\\AppData\\Roaming\\Python\\Python311\\site-packages\\ipykernel\\kernelbase.py\", line 529, in dispatch_queue\n\n  File \"C:\\Users\\ASUS\\AppData\\Roaming\\Python\\Python311\\site-packages\\ipykernel\\kernelbase.py\", line 518, in process_one\n\n  File \"C:\\Users\\ASUS\\AppData\\Roaming\\Python\\Python311\\site-packages\\ipykernel\\kernelbase.py\", line 424, in dispatch_shell\n\n  File \"C:\\Users\\ASUS\\AppData\\Roaming\\Python\\Python311\\site-packages\\ipykernel\\kernelbase.py\", line 766, in execute_request\n\n  File \"C:\\Users\\ASUS\\AppData\\Roaming\\Python\\Python311\\site-packages\\ipykernel\\ipkernel.py\", line 429, in do_execute\n\n  File \"C:\\Users\\ASUS\\AppData\\Roaming\\Python\\Python311\\site-packages\\ipykernel\\zmqshell.py\", line 549, in run_cell\n\n  File \"C:\\Users\\ASUS\\AppData\\Roaming\\Python\\Python311\\site-packages\\IPython\\core\\interactiveshell.py\", line 3048, in run_cell\n\n  File \"C:\\Users\\ASUS\\AppData\\Roaming\\Python\\Python311\\site-packages\\IPython\\core\\interactiveshell.py\", line 3103, in _run_cell\n\n  File \"C:\\Users\\ASUS\\AppData\\Roaming\\Python\\Python311\\site-packages\\IPython\\core\\async_helpers.py\", line 129, in _pseudo_sync_runner\n\n  File \"C:\\Users\\ASUS\\AppData\\Roaming\\Python\\Python311\\site-packages\\IPython\\core\\interactiveshell.py\", line 3308, in run_cell_async\n\n  File \"C:\\Users\\ASUS\\AppData\\Roaming\\Python\\Python311\\site-packages\\IPython\\core\\interactiveshell.py\", line 3490, in run_ast_nodes\n\n  File \"C:\\Users\\ASUS\\AppData\\Roaming\\Python\\Python311\\site-packages\\IPython\\core\\interactiveshell.py\", line 3550, in run_code\n\n  File \"C:\\Users\\ASUS\\AppData\\Local\\Temp\\ipykernel_18508\\886818541.py\", line 1, in <module>\n\n  File \"c:\\Users\\ASUS\\AppData\\Local\\Programs\\Python\\Python311\\Lib\\site-packages\\keras\\src\\utils\\traceback_utils.py\", line 65, in error_handler\n\n  File \"c:\\Users\\ASUS\\AppData\\Local\\Programs\\Python\\Python311\\Lib\\site-packages\\keras\\src\\engine\\training.py\", line 1807, in fit\n\n  File \"c:\\Users\\ASUS\\AppData\\Local\\Programs\\Python\\Python311\\Lib\\site-packages\\keras\\src\\engine\\training.py\", line 1401, in train_function\n\n  File \"c:\\Users\\ASUS\\AppData\\Local\\Programs\\Python\\Python311\\Lib\\site-packages\\keras\\src\\engine\\training.py\", line 1384, in step_function\n\n  File \"c:\\Users\\ASUS\\AppData\\Local\\Programs\\Python\\Python311\\Lib\\site-packages\\keras\\src\\engine\\training.py\", line 1373, in run_step\n\n  File \"c:\\Users\\ASUS\\AppData\\Local\\Programs\\Python\\Python311\\Lib\\site-packages\\keras\\src\\engine\\training.py\", line 1150, in train_step\n\n  File \"c:\\Users\\ASUS\\AppData\\Local\\Programs\\Python\\Python311\\Lib\\site-packages\\keras\\src\\utils\\traceback_utils.py\", line 65, in error_handler\n\n  File \"c:\\Users\\ASUS\\AppData\\Local\\Programs\\Python\\Python311\\Lib\\site-packages\\keras\\src\\engine\\training.py\", line 590, in __call__\n\n  File \"c:\\Users\\ASUS\\AppData\\Local\\Programs\\Python\\Python311\\Lib\\site-packages\\keras\\src\\utils\\traceback_utils.py\", line 65, in error_handler\n\n  File \"c:\\Users\\ASUS\\AppData\\Local\\Programs\\Python\\Python311\\Lib\\site-packages\\keras\\src\\engine\\base_layer.py\", line 1149, in __call__\n\n  File \"c:\\Users\\ASUS\\AppData\\Local\\Programs\\Python\\Python311\\Lib\\site-packages\\keras\\src\\utils\\traceback_utils.py\", line 96, in error_handler\n\n  File \"c:\\Users\\ASUS\\AppData\\Local\\Programs\\Python\\Python311\\Lib\\site-packages\\keras\\src\\engine\\sequential.py\", line 398, in call\n\n  File \"c:\\Users\\ASUS\\AppData\\Local\\Programs\\Python\\Python311\\Lib\\site-packages\\keras\\src\\engine\\functional.py\", line 515, in call\n\n  File \"c:\\Users\\ASUS\\AppData\\Local\\Programs\\Python\\Python311\\Lib\\site-packages\\keras\\src\\engine\\functional.py\", line 654, in _run_internal_graph\n\n  File \"c:\\Users\\ASUS\\AppData\\Local\\Programs\\Python\\Python311\\Lib\\site-packages\\keras\\src\\engine\\functional.py\", line 751, in _conform_to_reference_input\n\nCast string to float is not supported\n\t [[{{node sequential_8/Cast}}]] [Op:__inference_train_function_5128]"
     ]
    }
   ],
   "source": [
    "model.fit(X, y, epochs=100, batch_size=32)"
   ]
  }
 ],
 "metadata": {
  "kernelspec": {
   "display_name": "Python 3",
   "language": "python",
   "name": "python3"
  },
  "language_info": {
   "codemirror_mode": {
    "name": "ipython",
    "version": 3
   },
   "file_extension": ".py",
   "mimetype": "text/x-python",
   "name": "python",
   "nbconvert_exporter": "python",
   "pygments_lexer": "ipython3",
   "version": "3.11.2"
  }
 },
 "nbformat": 4,
 "nbformat_minor": 2
}
